Workbook
Name AD_list: Lookups!$A$2:$A$22
Name EF_List: Lookups!$E$2:$E$22

Sheet Activities
A1: Scope | B1: Category | C1: Activity | D1: Description | E1: Comments | F1: Activity Data Value | G1: Activity Data Unit | H1: Emission Factor | I1: EF Unit | J1: Calculated Total Emissions (tCO2e) | K1: AD Source | L1: EF Source | M1: CO2 EF (kg CO2 per Activity Data Unit) | N1: CH4 EF (kg CH4 per Activity Data Unit) | O1: N2O EF (kg N2O per Activity Data Unit) | P1: F-gas EF (kg F-gas per Activity Data Unit) | Q1: CO2 Emissions (tCO2) | R1: CH4 Emissions (tCO2e) | S1: N2O Emissions (tCO2e) | T1: Fluorinated Gas Emissions (tCO2e) | U1: Fluorinated Gas Mass (t F-gas)
A2: 1 | B2: stationary combusion | C2: Heters/boiler fuel gas firing | D2: Heters/boiler fuel gas firing - U_01 heater fuel firing | F2: 2687902 | G2: GJ | H2: =M2+N2*Lookups!$B$24+O2*Lookups!$B$25 -> 56.1545 | I2: kg CO2e/GJ | J2: =IF(Q2="","",Q2+R2+S2+IF(T2="",0,T2)) -> 150937.79 | K2: Well Calibrated Meter | L2: CO₂ from stationary fuel combustion using site-specific carbon content (lab) | M2: 56.1 | N2: 0.001 | O2: 0.0001 | Q2: =IF(OR(M2="",F2=""),"",F2*M2/1000) -> 150791.3 | R2: =IF(OR(N2="",F2=""),"",F2*N2/1000*Lookups!$B$24) -> 75.261256 | S2: =IF(OR(O2="",F2=""),"",F2*O2/1000*Lookups!$B$25) -> 71.229403 | T2: =IF(AND($B2="Fugitive emissions",$C2="Refrigerant leaks"),J2,"") | U2: =IF(AND($B2="Fugitive emissions",$C2="Refrigerant leaks"),F2/1000,"")
A3: 1 | B3: stationary combusion | C3: Heters/boiler fuel gas firing | D3: Heters/boiler fuel gas firing - U_17 heater fuel firing | F3: 2741660 | G3: GJ | H3: =M3+N3*Lookups!$B$24+O3*Lookups!$B$25 -> 56.1545 | I3: kg CO2e/GJ | J3: =IF(Q3="","",Q3+R3+S3+IF(T3="",0,T3)) -> 153956.55 | K3: Well Calibrated Meter | L3: CO₂ from stationary fuel combustion using site-specific carbon content (lab) | M3: 56.1 | N3: 0.001 | O3: 0.0001 | Q3: =IF(OR(M3="",F3=""),"",F3*M3/1000) -> 153807.13 | R3: =IF(OR(N3="",F3=""),"",F3*N3/1000*Lookups!$B$24) -> 76.76648 | S3: =IF(OR(O3="",F3=""),"",F3*O3/1000*Lookups!$B$25) -> 72.65399 | T3: =IF(AND($B3="Fugitive emissions",$C3="Refrigerant leaks"),J3,"") | U3: =IF(AND($B3="Fugitive emissions",$C3="Refrigerant leaks"),F3/1000,"")
A4: 1 | B4: stationary combusion | C4: Heters/boiler fuel gas firing | D4: Heters/boiler fuel gas firing - U02/03 heter firing | F4: 2795418 | G4: GJ | H4: =M4+N4*Lookups!$B$24+O4*Lookups!$B$25 -> 56.1545 | I4: kg CO2e/GJ | J4: =IF(Q4="","",Q4+R4+S4+IF(T4="",0,T4)) -> 156975.3 | K4: Well Calibrated Meter | L4: CO₂ from stationary fuel combustion using site-specific carbon content (lab) | M4: 56.1 | N4: 0.001 | O4: 0.0001 | Q4: =IF(OR(M4="",F4=""),"",F4*M4/1000) -> 156822.95 | R4: =IF(OR(N4="",F4=""),"",F4*N4/1000*Lookups!$B$24) -> 78.271704 | S4: =IF(OR(O4="",F4=""),"",F4*O4/1000*Lookups!$B$25) -> 74.078577 | T4: =IF(AND($B4="Fugitive emissions",$C4="Refrigerant leaks"),J4,"") | U4: =IF(AND($B4="Fugitive emissions",$C4="Refrigerant leaks"),F4/1000,"")
A5: 1 | B5: stationary combusion | C5: Heters/boiler fuel gas firing | D5: Heters/boiler fuel gas firing - U_04 heater firing | E5: Special Emission Factor | F5: 2849176 | G5: GJ | H5: =M5+N5*Lookups!$B$24+O5*Lookups!$B$25 -> 56.1545 | I5: kg CO2e/GJ | J5: =IF(Q5="","",Q5+R5+S5+IF(T5="",0,T5)) -> 159994.05 | K5: Well Calibrated Meter | L5: CO₂ from stationary fuel combustion using site-specific carbon content (lab) | M5: 56.1 | N5: 0.001 | O5: 0.0001 | Q5: =IF(OR(M5="",F5=""),"",F5*M5/1000) -> 159838.77 | R5: =IF(OR(N5="",F5=""),"",F5*N5/1000*Lookups!$B$24) -> 79.776928 | S5: =IF(OR(O5="",F5=""),"",F5*O5/1000*Lookups!$B$25) -> 75.503164 | T5: =IF(AND($B5="Fugitive emissions",$C5="Refrigerant leaks"),J5,"") | U5: =IF(AND($B5="Fugitive emissions",$C5="Refrigerant leaks"),F5/1000,"")
A6: 1 | B6: stationary combusion | C6: Heters/boiler fuel gas firing | D6: Heters/boiler fuel gas firing - U_07 heter firing | F6: 2902934 | G6: GJ | H6: =M6+N6*Lookups!$B$24+O6*Lookups!$B$25 -> 56.1545 | I6: kg CO2e/GJ | J6: =IF(Q6="","",Q6+R6+S6+IF(T6="",0,T6)) -> 163012.81 | K6: Well Calibrated Meter | L6: CO₂ from stationary fuel combustion using site-specific carbon content (lab) | M6: 56.1 | N6: 0.001 | O6: 0.0001 | Q6: =IF(OR(M6="",F6=""),"",F6*M6/1000) -> 162854.6 | R6: =IF(OR(N6="",F6=""),"",F6*N6/1000*Lookups!$B$24) -> 81.282152 | S6: =IF(OR(O6="",F6=""),"",F6*O6/1000*Lookups!$B$25) -> 76.927751 | T6: =IF(AND($B6="Fugitive emissions",$C6="Refrigerant leaks"),J6,"") | U6: =IF(AND($B6="Fugitive emissions",$C6="Refrigerant leaks"),F6/1000,"")
A7: 1 | B7: stationary combusion | C7: Heters/boiler fuel gas firing | D7: Heters/boiler fuel gas firing - U_08 heater firing | F7: 2956692 | G7: GJ | H7: =M7+N7*Lookups!$B$24+O7*Lookups!$B$25 -> 56.1545 | I7: kg CO2e/GJ | J7: =IF(Q7="","",Q7+R7+S7+IF(T7="",0,T7)) -> 166031.56 | K7: Well Calibrated Meter | L7: CO₂ from stationary fuel combustion using site-specific carbon content (lab) | M7: 56.1 | N7: 0.001 | O7: 0.0001 | Q7: =IF(OR(M7="",F7=""),"",F7*M7/1000) -> 165870.42 | R7: =IF(OR(N7="",F7=""),"",F7*N7/1000*Lookups!$B$24) -> 82.787376 | S7: =IF(OR(O7="",F7=""),"",F7*O7/1000*Lookups!$B$25) -> 78.352338 | T7: =IF(AND($B7="Fugitive emissions",$C7="Refrigerant leaks"),J7,"") | U7: =IF(AND($B7="Fugitive emissions",$C7="Refrigerant leaks"),F7/1000,"")
A8: 1 | B8: stationary combusion | C8: Heters/boiler fuel gas firing | D8: Heters/boiler fuel gas firing - U_09 heater firing | F8: 3010450 | G8: GJ | H8: =M8+N8*Lookups!$B$24+O8*Lookups!$B$25 -> 56.1545 | I8: kg CO2e/GJ | J8: =IF(Q8="","",Q8+R8+S8+IF(T8="",0,T8)) -> 169050.31 | K8: Well Calibrated Meter | L8: CO₂ from stationary fuel combustion using site-specific carbon content (lab) | M8: 56.1 | N8: 0.001 | O8: 0.0001 | Q8: =IF(OR(M8="",F8=""),"",F8*M8/1000) -> 168886.24 | R8: =IF(OR(N8="",F8=""),"",F8*N8/1000*Lookups!$B$24) -> 84.2926 | S8: =IF(OR(O8="",F8=""),"",F8*O8/1000*Lookups!$B$25) -> 79.776925 | T8: =IF(AND($B8="Fugitive emissions",$C8="Refrigerant leaks"),J8,"") | U8: =IF(AND($B8="Fugitive emissions",$C8="Refrigerant leaks"),F8/1000,"")
A9: 1 | B9: stationary combusion | C9: Heters/boiler fuel gas firing | D9: Heters/boiler fuel gas firing - U_11 heater firing | F9: 3064208 | G9: GJ | H9: =M9+N9*Lookups!$B$24+O9*Lookups!$B$25 -> 56.1545 | I9: kg CO2e/GJ | J9: =IF(Q9="","",Q9+R9+S9+IF(T9="",0,T9)) -> 172069.07 | K9: Well Calibrated Meter | L9: CO₂ from stationary fuel combustion using site-specific carbon content (lab) | M9: 56.1 | N9: 0.001 | O9: 0.0001 | Q9: =IF(OR(M9="",F9=""),"",F9*M9/1000) -> 171902.07 | R9: =IF(OR(N9="",F9=""),"",F9*N9/1000*Lookups!$B$24) -> 85.797824 | S9: =IF(OR(O9="",F9=""),"",F9*O9/1000*Lookups!$B$25) -> 81.201512 | T9: =IF(AND($B9="Fugitive emissions",$C9="Refrigerant leaks"),J9,"") | U9: =IF(AND($B9="Fugitive emissions",$C9="Refrigerant leaks"),F9/1000,"")
A10: 1 | B10: stationary combusion | C10: Heters/boiler fuel gas firing | D10: Heters/boiler fuel gas firing - U_11_cell3 heater firing | F10: 3117966 | G10: GJ | H10: =M10+N10*Lookups!$B$24+O10*Lookups!$B$25 -> 56.1545 | I10: kg CO2e/GJ | J10: =IF(Q10="","",Q10+R10+S10+IF(T10="",0,T10)) -> 175087.82 | K10: Well Calibrated Meter | L10: CO₂ from stationary fuel combustion using site-specific carbon content (lab) | M10: 56.1 | N10: 0.001 | O10: 0.0001 | Q10: =IF(OR(M10="",F10=""),"",F10*M10/1000) -> 174917.89 | R10: =IF(OR(N10="",F10=""),"",F10*N10/1000*Lookups!$B$24) -> 87.303048 | S10: =IF(OR(O10="",F10=""),"",F10*O10/1000*Lookups!$B$25) -> 82.626099 | T10: =IF(AND($B10="Fugitive emissions",$C10="Refrigerant leaks"),J10,"") | U10: =IF(AND($B10="Fugitive emissions",$C10="Refrigerant leaks"),F10/1000,"")
A11: 1 | B11: stationary combusion | C11: Heters/boiler fuel gas firing | D11: Heters/boiler fuel gas firing - U_18 heater firing | F11: 3171724 | G11: GJ | H11: =M11+N11*Lookups!$B$24+O11*Lookups!$B$25 -> 56.1545 | I11: kg CO2e/GJ | J11: =IF(Q11="","",Q11+R11+S11+IF(T11="",0,T11)) -> 178106.58 | K11: Well Calibrated Meter | L11: CO₂ from stationary fuel combustion using site-specific carbon content (lab) | M11: 56.1 | N11: 0.001 | O11: 0.0001 | Q11: =IF(OR(M11="",F11=""),"",F11*M11/1000) -> 177933.72 | R11: =IF(OR(N11="",F11=""),"",F11*N11/1000*Lookups!$B$24) -> 88.808272 | S11: =IF(OR(O11="",F11=""),"",F11*O11/1000*Lookups!$B$25) -> 84.050686 | T11: =IF(AND($B11="Fugitive emissions",$C11="Refrigerant leaks"),J11,"") | U11: =IF(AND($B11="Fugitive emissions",$C11="Refrigerant leaks"),F11/1000,"")
A12: 1 | B12: stationary combusion | C12: Heters/boiler fuel gas firing | D12: Heters/boiler fuel gas firing - U_19 heater firing | F12: 3225482 | G12: GJ | H12: =M12+N12*Lookups!$B$24+O12*Lookups!$B$25 -> 56.1545 | I12: kg CO2e/GJ | J12: =IF(Q12="","",Q12+R12+S12+IF(T12="",0,T12)) -> 181125.33 | K12: Well Calibrated Meter | L12: CO₂ from stationary fuel combustion using site-specific carbon content (lab) | M12: 56.1 | N12: 0.001 | O12: 0.0001 | Q12: =IF(OR(M12="",F12=""),"",F12*M12/1000) -> 180949.54 | R12: =IF(OR(N12="",F12=""),"",F12*N12/1000*Lookups!$B$24) -> 90.313496 | S12: =IF(OR(O12="",F12=""),"",F12*O12/1000*Lookups!$B$25) -> 85.475273 | T12: =IF(AND($B12="Fugitive emissions",$C12="Refrigerant leaks"),J12,"") | U12: =IF(AND($B12="Fugitive emissions",$C12="Refrigerant leaks"),F12/1000,"")
A13: 1 | B13: stationary combusion | C13: Heters/boiler fuel gas firing | D13: Heters/boiler fuel gas firing - U_20 heater firing | F13: 3279240 | G13: GJ | H13: =M13+N13*Lookups!$B$24+O13*Lookups!$B$25 -> 56.1545 | I13: kg CO2e/GJ | J13: =IF(Q13="","",Q13+R13+S13+IF(T13="",0,T13)) -> 184144.08 | K13: Well Calibrated Meter | L13: CO₂ from stationary fuel combustion using site-specific carbon content (lab) | M13: 56.1 | N13: 0.001 | O13: 0.0001 | Q13: =IF(OR(M13="",F13=""),"",F13*M13/1000) -> 183965.36 | R13: =IF(OR(N13="",F13=""),"",F13*N13/1000*Lookups!$B$24) -> 91.81872 | S13: =IF(OR(O13="",F13=""),"",F13*O13/1000*Lookups!$B$25) -> 86.89986 | T13: =IF(AND($B13="Fugitive emissions",$C13="Refrigerant leaks"),J13,"") | U13: =IF(AND($B13="Fugitive emissions",$C13="Refrigerant leaks"),F13/1000,"")
A14: 1 | B14: stationary combusion | C14: Heters/boiler fuel gas firing | D14: Heters/boiler fuel gas firing - U_21 heater firing | F14: 3332998 | G14: GJ | H14: =M14+N14*Lookups!$B$24+O14*Lookups!$B$25 -> 56.1545 | I14: kg CO2e/GJ | J14: =IF(Q14="","",Q14+R14+S14+IF(T14="",0,T14)) -> 187162.84 | K14: Well Calibrated Meter | L14: CO₂ from stationary fuel combustion using site-specific carbon content (lab) | M14: 56.1 | N14: 0.001 | O14: 0.0001 | Q14: =IF(OR(M14="",F14=""),"",F14*M14/1000) -> 186981.19 | R14: =IF(OR(N14="",F14=""),"",F14*N14/1000*Lookups!$B$24) -> 93.323944 | S14: =IF(OR(O14="",F14=""),"",F14*O14/1000*Lookups!$B$25) -> 88.324447 | T14: =IF(AND($B14="Fugitive emissions",$C14="Refrigerant leaks"),J14,"") | U14: =IF(AND($B14="Fugitive emissions",$C14="Refrigerant leaks"),F14/1000,"")
A15: 1 | B15: stationary combusion | C15: Heters/boiler fuel gas firing | D15: Heters/boiler fuel gas firing - U_37 boilers firing | F15: 3386756 | G15: GJ | H15: =M15+N15*Lookups!$B$24+O15*Lookups!$B$25 -> 56.1545 | I15: kg CO2e/GJ | J15: =IF(Q15="","",Q15+R15+S15+IF(T15="",0,T15)) -> 190181.59 | K15: Well Calibrated Meter | L15: CO₂ from stationary fuel combustion using site-specific carbon content (lab) | M15: 56.1 | N15: 0.001 | O15: 0.0001 | Q15: =IF(OR(M15="",F15=""),"",F15*M15/1000) -> 189997.01 | R15: =IF(OR(N15="",F15=""),"",F15*N15/1000*Lookups!$B$24) -> 94.829168 | S15: =IF(OR(O15="",F15=""),"",F15*O15/1000*Lookups!$B$25) -> 89.749034 | T15: =IF(AND($B15="Fugitive emissions",$C15="Refrigerant leaks"),J15,"") | U15: =IF(AND($B15="Fugitive emissions",$C15="Refrigerant leaks"),F15/1000,"")
A16: 1 | B16: stationary combusion | C16: Incenerator firing | D16: Incenerator firing - U_13 firing | F16: 1720257 | G16: GJ | H16: =M16+N16*Lookups!$B$24+O16*Lookups!$B$25 -> 58.0545 | I16: kg CO2e/GJ | J16: =IF(Q16="","",Q16+R16+S16+IF(T16="",0,T16)) -> 99868.66 | K16: Well Calibrated Meter | L16: CO₂ from stationary fuel combustion using site-specific carbon content (lab) | M16: 58 | N16: 0.001 | O16: 0.0001 | Q16: =IF(OR(M16="",F16=""),"",F16*M16/1000) -> 99774.906 | R16: =IF(OR(N16="",F16=""),"",F16*N16/1000*Lookups!$B$24) -> 48.167196 | S16: =IF(OR(O16="",F16=""),"",F16*O16/1000*Lookups!$B$25) -> 45.58681 | T16: =IF(AND($B16="Fugitive emissions",$C16="Refrigerant leaks"),J16,"") | U16: =IF(AND($B16="Fugitive emissions",$C16="Refrigerant leaks"),F16/1000,"")
A17: 1 | B17: stationary combusion | C17: Incenerator firing | D17: Incenerator firing - U_22 firing | F17: 1747136 | G17: GJ | H17: =M17+N17*Lookups!$B$24+O17*Lookups!$B$25 -> 58.0545 | I17: kg CO2e/GJ | J17: =IF(Q17="","",Q17+R17+S17+IF(T17="",0,T17)) -> 101429.11 | K17: Well Calibrated Meter | L17: CO₂ from stationary fuel combustion using site-specific carbon content (lab) | M17: 58 | N17: 0.001 | O17: 0.0001 | Q17: =IF(OR(M17="",F17=""),"",F17*M17/1000) -> 101333.89 | R17: =IF(OR(N17="",F17=""),"",F17*N17/1000*Lookups!$B$24) -> 48.919808 | S17: =IF(OR(O17="",F17=""),"",F17*O17/1000*Lookups!$B$25) -> 46.299104 | T17: =IF(AND($B17="Fugitive emissions",$C17="Refrigerant leaks"),J17,"") | U17: =IF(AND($B17="Fugitive emissions",$C17="Refrigerant leaks"),F17/1000,"")
A18: 1 | B18: stationary combusion | C18: Fuel oil firing | D18: Fuel oil firing | E18: U_01 heater | F18: 15000 | G18: GJ | H18: =M18+N18*Lookups!$B$24+O18*Lookups!$B$25 -> 77.643 | I18: kg CO2e/GJ | J18: =IF(Q18="","",Q18+R18+S18+IF(T18="",0,T18)) -> 1164.645 | K18: Well Calibrated Meter | L18: CO₂ from stationary fuel combustion using site-specific carbon content (lab) | M18: 77.4 | N18: 0.003 | O18: 0.0006 | Q18: =IF(OR(M18="",F18=""),"",F18*M18/1000) -> 1161 | R18: =IF(OR(N18="",F18=""),"",F18*N18/1000*Lookups!$B$24) -> 1.26 | S18: =IF(OR(O18="",F18=""),"",F18*O18/1000*Lookups!$B$25) -> 2.385 | T18: =IF(AND($B18="Fugitive emissions",$C18="Refrigerant leaks"),J18,"") | U18: =IF(AND($B18="Fugitive emissions",$C18="Refrigerant leaks"),F18/1000,"")
A19: 1 | B19: stationary combusion | C19: Diesel firing | D19: Diesel firing - Electric substations | F19: 10000 | G19: L | H19: =M19+N19*Lookups!$B$24+O19*Lookups!$B$25 -> 2.6887745 | I19: kg CO2e/L | J19: =IF(Q19="","",Q19+R19+S19+IF(T19="",0,T19)) -> 26.887745 | K19: Supplier Invoices | L19: DEFRA 2024 conversion factors / 2021-API-GHG-Compendium with conversion from KG CO2e /MMBTU to KG CO2e/Litre | M19: 2.68 | N19: 0.000108 | O19: 2.17e-05 | Q19: =IF(OR(M19="",F19=""),"",F19*M19/1000) -> 26.8 | R19: =IF(OR(N19="",F19=""),"",F19*N19/1000*Lookups!$B$24) -> 0.03024 | S19: =IF(OR(O19="",F19=""),"",F19*O19/1000*Lookups!$B$25) -> 0.057505 | T19: =IF(AND($B19="Fugitive emissions",$C19="Refrigerant leaks"),J19,"") | U19: =IF(AND($B19="Fugitive emissions",$C19="Refrigerant leaks"),F19/1000,"")
A20: 1 | B20: stationary combusion | C20: Diesel firing | D20: Diesel firing - Disel Fire pumps | F20: 6000 | G20: L | H20: =M20+N20*Lookups!$B$24+O20*Lookups!$B$25 -> 2.6887745 | I20: kg CO2e/L | J20: =IF(Q20="","",Q20+R20+S20+IF(T20="",0,T20)) -> 16.132647 | K20: Supplier Invoices | L20: DEFRA 2024 conversion factors / 2021-API-GHG-Compendium with conversion from KG CO2e /MMBTU to KG CO2e/Litre | M20: 2.68 | N20: 0.000108 | O20: 2.17e-05 | Q20: =IF(OR(M20="",F20=""),"",F20*M20/1000) -> 16.08 | R20: =IF(OR(N20="",F20=""),"",F20*N20/1000*Lookups!$B$24) -> 0.018144 | S20: =IF(OR(O20="",F20=""),"",F20*O20/1000*Lookups!$B$25) -> 0.034503 | T20: =IF(AND($B20="Fugitive emissions",$C20="Refrigerant leaks"),J20,"") | U20: =IF(AND($B20="Fugitive emissions",$C20="Refrigerant leaks"),F20/1000,"")
A21: 1 | B21: Mobile combusion | C21: Diesel | D21: Diesel - Forklifts | F21: 180000 | G21: L diesel | H21: =M21+N21*Lookups!$B$24+O21*Lookups!$B$25 -> 2.721313 | I21: kg CO2e/L | J21: =IF(Q21="","",Q21+R21+S21+IF(T21="",0,T21)) -> 489.83634 | K21: Supplier Invoices | L21: DEFRA 2024 conversion factors / 2021-API-GHG-Compendium with conversion from KG CO2e /MMBTU to KG CO2e/Litre | M21: 2.68 | N21: 0.000141 | O21: 0.000141 | Q21: =IF(OR(M21="",F21=""),"",F21*M21/1000) -> 482.4 | R21: =IF(OR(N21="",F21=""),"",F21*N21/1000*Lookups!$B$24) -> 0.71064 | S21: =IF(OR(O21="",F21=""),"",F21*O21/1000*Lookups!$B$25) -> 6.7257 | T21: =IF(AND($B21="Fugitive emissions",$C21="Refrigerant leaks"),J21,"") | U21: =IF(AND($B21="Fugitive emissions",$C21="Refrigerant leaks"),F21/1000,"")
A22: 1 | B22: Mobile combusion | C22: Diesel | D22: Diesel - Fire vehicle | F22: 20000 | G22: L diesel | H22: =M22+N22*Lookups!$B$24+O22*Lookups!$B$25 -> 2.721313 | I22: kg CO2e/L | J22: =IF(Q22="","",Q22+R22+S22+IF(T22="",0,T22)) -> 54.42626 | K22: Supplier Invoices | L22: DEFRA 2024 conversion factors / 2021-API-GHG-Compendium with conversion from KG CO2e /MMBTU to KG CO2e/Litre | M22: 2.68 | N22: 0.000141 | O22: 0.000141 | Q22: =IF(OR(M22="",F22=""),"",F22*M22/1000) -> 53.6 | R22: =IF(OR(N22="",F22=""),"",F22*N22/1000*Lookups!$B$24) -> 0.07896 | S22: =IF(OR(O22="",F22=""),"",F22*O22/1000*Lookups!$B$25) -> 0.7473 | T22: =IF(AND($B22="Fugitive emissions",$C22="Refrigerant leaks"),J22,"") | U22: =IF(AND($B22="Fugitive emissions",$C22="Refrigerant leaks"),F22/1000,"")
A23: 1 | B23: Mobile combusion | C23: Diesel | D23: Diesel - maintinance vehicles | F23: 28500 | G23: L diesel | H23: =M23+N23*Lookups!$B$24+O23*Lookups!$B$25 -> 2.721313 | I23: kg CO2e/L | J23: =IF(Q23="","",Q23+R23+S23+IF(T23="",0,T23)) -> 77.55742 | K23: Supplier Invoices | L23: DEFRA 2024 conversion factors / 2021-API-GHG-Compendium with conversion from KG CO2e /MMBTU to KG CO2e/Litre | M23: 2.68 | N23: 0.000141 | O23: 0.000141 | Q23: =IF(OR(M23="",F23=""),"",F23*M23/1000) -> 76.38 | R23: =IF(OR(N23="",F23=""),"",F23*N23/1000*Lookups!$B$24) -> 0.112518 | S23: =IF(OR(O23="",F23=""),"",F23*O23/1000*Lookups!$B$25) -> 1.0649025 | T23: =IF(AND($B23="Fugitive emissions",$C23="Refrigerant leaks"),J23,"") | U23: =IF(AND($B23="Fugitive emissions",$C23="Refrigerant leaks"),F23/1000,"")
A24: 1 | B24: Mobile combusion | C24: Diesel | D24: Diesel - shuttle/Bus movements | F24: 29000 | G24: L diesel | H24: =M24+N24*Lookups!$B$24+O24*Lookups!$B$25 -> 2.721313 | I24: kg CO2e/L | J24: =IF(Q24="","",Q24+R24+S24+IF(T24="",0,T24)) -> 78.918077 | K24: Supplier Invoices | L24: DEFRA 2024 conversion factors / 2021-API-GHG-Compendium with conversion from KG CO2e /MMBTU to KG CO2e/Litre | M24: 2.68 | N24: 0.000141 | O24: 0.000141 | Q24: =IF(OR(M24="",F24=""),"",F24*M24/1000) -> 77.72 | R24: =IF(OR(N24="",F24=""),"",F24*N24/1000*Lookups!$B$24) -> 0.114492 | S24: =IF(OR(O24="",F24=""),"",F24*O24/1000*Lookups!$B$25) -> 1.083585 | T24: =IF(AND($B24="Fugitive emissions",$C24="Refrigerant leaks"),J24,"") | U24: =IF(AND($B24="Fugitive emissions",$C24="Refrigerant leaks"),F24/1000,"")
A25: 1 | B25: Fugitive emissions | C25: Storage tanks breathing & working losses | D25: Storage tanks breathing & working losses - Crude Tanks | F25: 8124251 | G25: m3 throughput | H25: =M25+N25*Lookups!$B$24+O25*Lookups!$B$25 -> 0.15 | I25: kg CO2e/m3 | J25: =IF(Q25="","",Q25+R25+S25+IF(T25="",0,T25)) -> 1218.6376 | K25: Well Calibrated Meter | L25: EPA AP- 42 to calculate Evaporative emissions from tanks then /DEFRA 2024 conversion factors | M25: 0.15 | N25: 0 | O25: 0 | Q25: =IF(OR(M25="",F25=""),"",F25*M25/1000) -> 1218.6376 | R25: =IF(OR(N25="",F25=""),"",F25*N25/1000*Lookups!$B$24) -> 0 | S25: =IF(OR(O25="",F25=""),"",F25*O25/1000*Lookups!$B$25) -> 0 | T25: =IF(AND($B25="Fugitive emissions",$C25="Refrigerant leaks"),J25,"") | U25: =IF(AND($B25="Fugitive emissions",$C25="Refrigerant leaks"),F25/1000,"")
A26: 1 | B26: Fugitive emissions | C26: Storage tanks breathing & working losses | D26: Storage tanks breathing & working losses - LPG tanks | F26: 406213 | G26: m3 throughput | H26: =M26+N26*Lookups!$B$24+O26*Lookups!$B$25 -> 0.15 | I26: kg CO2e/m3 | J26: =IF(Q26="","",Q26+R26+S26+IF(T26="",0,T26)) -> 60.93195 | K26: Well Calibrated Meter | L26: EPA AP- 42 to calculate Evaporative emissions from tanks then /DEFRA 2024 conversion factors | M26: 0.15 | N26: 0 | O26: 0 | Q26: =IF(OR(M26="",F26=""),"",F26*M26/1000) -> 60.93195 | R26: =IF(OR(N26="",F26=""),"",F26*N26/1000*Lookups!$B$24) -> 0 | S26: =IF(OR(O26="",F26=""),"",F26*O26/1000*Lookups!$B$25) -> 0 | T26: =IF(AND($B26="Fugitive emissions",$C26="Refrigerant leaks"),J26,"") | U26: =IF(AND($B26="Fugitive emissions",$C26="Refrigerant leaks"),F26/1000,"")
A27: 1 | B27: Fugitive emissions | C27: Storage tanks breathing & working losses | D27: Storage tanks breathing & working losses - Naphtha Tanks | F27: 2031063 | G27: m3 throughput | H27: =M27+N27*Lookups!$B$24+O27*Lookups!$B$25 -> 0.15 | I27: kg CO2e/m3 | J27: =IF(Q27="","",Q27+R27+S27+IF(T27="",0,T27)) -> 304.65945 | K27: Well Calibrated Meter | L27: EPA AP- 42 to calculate Evaporative emissions from tanks then /DEFRA 2024 conversion factors | M27: 0.15 | N27: 0 | O27: 0 | Q27: =IF(OR(M27="",F27=""),"",F27*M27/1000) -> 304.65945 | R27: =IF(OR(N27="",F27=""),"",F27*N27/1000*Lookups!$B$24) -> 0 | S27: =IF(OR(O27="",F27=""),"",F27*O27/1000*Lookups!$B$25) -> 0 | T27: =IF(AND($B27="Fugitive emissions",$C27="Refrigerant leaks"),J27,"") | U27: =IF(AND($B27="Fugitive emissions",$C27="Refrigerant leaks"),F27/1000,"")
A28: 1 | B28: Fugitive emissions | C28: Storage tanks breathing & working losses | D28: Storage tanks breathing & working losses - Kerosene Tanks | F28: 812425 | G28: m3 throughput | H28: =M28+N28*Lookups!$B$24+O28*Lookups!$B$25 -> 0.15 | I28: kg CO2e/m3 | J28: =IF(Q28="","",Q28+R28+S28+IF(T28="",0,T28)) -> 121.86375 | K28: Well Calibrated Meter | L28: EPA AP- 42 to calculate Evaporative emissions from tanks then /DEFRA 2024 conversion factors | M28: 0.15 | N28: 0 | O28: 0 | Q28: =IF(OR(M28="",F28=""),"",F28*M28/1000) -> 121.86375 | R28: =IF(OR(N28="",F28=""),"",F28*N28/1000*Lookups!$B$24) -> 0 | S28: =IF(OR(O28="",F28=""),"",F28*O28/1000*Lookups!$B$25) -> 0 | T28: =IF(AND($B28="Fugitive emissions",$C28="Refrigerant leaks"),J28,"") | U28: =IF(AND($B28="Fugitive emissions",$C28="Refrigerant leaks"),F28/1000,"")
A29: 1 | B29: Fugitive emissions | C29: Storage tanks breathing & working losses | D29: Storage tanks breathing & working losses - Diesel Tanks | F29: 2843488 | G29: m3 throughput | H29: =M29+N29*Lookups!$B$24+O29*Lookups!$B$25 -> 0.15 | I29: kg CO2e/m3 | J29: =IF(Q29="","",Q29+R29+S29+IF(T29="",0,T29)) -> 426.5232 | K29: Well Calibrated Meter | L29: EPA AP- 42 to calculate Evaporative emissions from tanks then /DEFRA 2024 conversion factors | M29: 0.15 | N29: 0 | O29: 0 | Q29: =IF(OR(M29="",F29=""),"",F29*M29/1000) -> 426.5232 | R29: =IF(OR(N29="",F29=""),"",F29*N29/1000*Lookups!$B$24) -> 0 | S29: =IF(OR(O29="",F29=""),"",F29*O29/1000*Lookups!$B$25) -> 0 | T29: =IF(AND($B29="Fugitive emissions",$C29="Refrigerant leaks"),J29,"") | U29: =IF(AND($B29="Fugitive emissions",$C29="Refrigerant leaks"),F29/1000,"")
A30: 1 | B30: Fugitive emissions | C30: Product loading/unloading | D30: Product loading/unloading | E30: Truck loading | F30: 6336916 | G30: m3 loaded | H30: =M30+N30*Lookups!$B$24+O30*Lookups!$B$25 -> 0.12 | I30: kg CO2e/m3 | J30: =IF(Q30="","",Q30+R30+S30+IF(T30="",0,T30)) -> 760.42992 | K30: Well Calibrated Meter | L30: EPA AP- 42 to calculate Evaporative emissions from tanks then /DEFRA 2024 conversion factors | M30: 0.12 | N30: 0 | O30: 0 | Q30: =IF(OR(M30="",F30=""),"",F30*M30/1000) -> 760.42992 | R30: =IF(OR(N30="",F30=""),"",F30*N30/1000*Lookups!$B$24) -> 0 | S30: =IF(OR(O30="",F30=""),"",F30*O30/1000*Lookups!$B$25) -> 0 | T30: =IF(AND($B30="Fugitive emissions",$C30="Refrigerant leaks"),J30,"") | U30: =IF(AND($B30="Fugitive emissions",$C30="Refrigerant leaks"),F30/1000,"")
A31: 1 | B31: Fugitive emissions | C31: Fire extinguishers | D31: Fire extinguishers | E31: From all Co2 fire extinguishers in the refinery | F31: 200 | G31: kg CO2 | H31: =M31+N31*Lookups!$B$24+O31*Lookups!$B$25 -> 1 | I31: kg CO2e/kg CO2 | J31: =IF(Q31="","",Q31+R31+S31+IF(T31="",0,T31)) -> 0.2 | K31: Supplier Invoices | L31: DEFRA 2024 conversion factors | M31: 1 | N31: 0 | O31: 0 | Q31: =IF(OR(M31="",F31=""),"",F31*M31/1000) -> 0.2 | R31: =IF(OR(N31="",F31=""),"",F31*N31/1000*Lookups!$B$24) -> 0 | S31: =IF(OR(O31="",F31=""),"",F31*O31/1000*Lookups!$B$25) -> 0 | T31: =IF(AND($B31="Fugitive emissions",$C31="Refrigerant leaks"),J31,"") | U31: =IF(AND($B31="Fugitive emissions",$C31="Refrigerant leaks"),F31/1000,"")
A32: 1 | B32: Fugitive emissions | C32: Refrigerant leaks | D32: Refrigerant leaks - R-134a | F32: 45 | G32: kg refrigerant | H32: 1.3 | I32: tCO2e/kg refrigerant | J32: =IF(Q32="","",Q32+R32+S32+IF(T32="",0,T32)) -> 58.5 | K32: Supplier Invoices | L32: DEFRA 2024 conversion factors | M32: 0 | N32: 0 | O32: 0 | P32: 45 | Q32: =IF(OR(M32="",F32=""),"",F32*M32/1000) -> 0 | R32: =IF(OR(N32="",F32=""),"",F32*N32/1000*Lookups!$B$24) -> 0 | S32: =IF(OR(O32="",F32=""),"",F32*O32/1000*Lookups!$B$25) -> 0 | T32: =IF(AND($B32="Fugitive emissions",$C32="Refrigerant leaks"),F32*H32,"") -> 58.5 | U32: =IF(AND($B32="Fugitive emissions",$C32="Refrigerant leaks"),F32/1000,"") -> 0.045
A33: 1 | B33: Fugitive emissions | C33: Refrigerant leaks | D33: Refrigerant leaks - R-410a | F33: 60 | G33: kg refrigerant | H33: 1.9235 | I33: tCO2e/kg refrigerant | J33: =IF(Q33="","",Q33+R33+S33+IF(T33="",0,T33)) -> 115.41 | K33: Supplier Invoices | L33: DEFRA 2024 conversion factors | M33: 0 | N33: 0 | O33: 0 | P33: 60 | Q33: =IF(OR(M33="",F33=""),"",F33*M33/1000) -> 0 | R33: =IF(OR(N33="",F33=""),"",F33*N33/1000*Lookups!$B$24) -> 0 | S33: =IF(OR(O33="",F33=""),"",F33*O33/1000*Lookups!$B$25) -> 0 | T33: =IF(AND($B33="Fugitive emissions",$C33="Refrigerant leaks"),F33*H33,"") -> 115.41 | U33: =IF(AND($B33="Fugitive emissions",$C33="Refrigerant leaks"),F33/1000,"") -> 0.06
A34: 1 | B34: Fugitive emissions | C34: Refrigerant leaks | D34: Refrigerant leaks - R-407c | F34: 30 | G34: kg refrigerant | H34: 1.62421 | I34: tCO2e/kg refrigerant | J34: =IF(Q34="","",Q34+R34+S34+IF(T34="",0,T34)) -> 48.7263 | K34: Supplier Invoices | L34: DEFRA 2024 conversion factors | M34: 0 | N34: 0 | O34: 0 | P34: 30 | Q34: =IF(OR(M34="",F34=""),"",F34*M34/1000) -> 0 | R34: =IF(OR(N34="",F34=""),"",F34*N34/1000*Lookups!$B$24) -> 0 | S34: =IF(OR(O34="",F34=""),"",F34*O34/1000*Lookups!$B$25) -> 0 | T34: =IF(AND($B34="Fugitive emissions",$C34="Refrigerant leaks"),F34*H34,"") -> 48.7263 | U34: =IF(AND($B34="Fugitive emissions",$C34="Refrigerant leaks"),F34/1000,"") -> 0.03
A35: 1 | B35: Fugitive emissions | C35: Refrigerant leaks | D35: Refrigerant leaks - R-404a | F35: 15 | G35: kg refrigerant | H35: 3.9428 | I35: tCO2e/kg refrigerant | J35: =IF(Q35="","",Q35+R35+S35+IF(T35="",0,T35)) -> 59.142 | K35: Supplier Invoices | L35: DEFRA 2024 conversion factors | M35: 0 | N35: 0 | O35: 0 | P35: 15 | Q35: =IF(OR(M35="",F35=""),"",F35*M35/1000) -> 0 | R35: =IF(OR(N35="",F35=""),"",F35*N35/1000*Lookups!$B$24) -> 0 | S35: =IF(OR(O35="",F35=""),"",F35*O35/1000*Lookups!$B$25) -> 0 | T35: =IF(AND($B35="Fugitive emissions",$C35="Refrigerant leaks"),F35*H35,"") -> 59.142 | U35: =IF(AND($B35="Fugitive emissions",$C35="Refrigerant leaks"),F35/1000,"") -> 0.015
A36: 1 | B36: Process Emission | C36: Catalyst regeneration | D36: Catalyst regeneration | E36: U_04 regen tower | F36: 45000 | G36: kg catalyst | H36: =M36+N36*Lookups!$B$24+O36*Lookups!$B$25 -> 3.2 | I36: kg CO2e/kg catalyst | J36: =IF(Q36="","",Q36+R36+S36+IF(T36="",0,T36)) -> 144 | K36: Coke burn by mass balance / air flow + composition routinely monitored | L36: CO₂ (coke burn / flue gas mass balance) | M36: 3.2 | N36: 0 | O36: 0 | Q36: =IF(OR(M36="",F36=""),"",F36*M36/1000) -> 144 | R36: =IF(OR(N36="",F36=""),"",F36*N36/1000*Lookups!$B$24) -> 0 | S36: =IF(OR(O36="",F36=""),"",F36*O36/1000*Lookups!$B$25) -> 0 | T36: =IF(AND($B36="Fugitive emissions",$C36="Refrigerant leaks"),J36,"") | U36: =IF(AND($B36="Fugitive emissions",$C36="Refrigerant leaks"),F36/1000,"")
A37: 1 | B37: Process Emission | C37: Coke drum steaming out | D37: Coke drum steaming out | E37: U_11 steaming out | F37: 30000 | G37: tons coke | H37: =M37+N37*Lookups!$B$24+O37*Lookups!$B$25 -> 1.5 | I37: kg CO2e/ton coke | J37: =IF(Q37="","",Q37+R37+S37+IF(T37="",0,T37)) -> 45 | K37: Coke burn by mass balance / air flow + composition routinely monitored | L37: CO₂ (coke burn / flue gas mass balance) | M37: 1.5 | N37: 0 | O37: 0 | Q37: =IF(OR(M37="",F37=""),"",F37*M37/1000) -> 45 | R37: =IF(OR(N37="",F37=""),"",F37*N37/1000*Lookups!$B$24) -> 0 | S37: =IF(OR(O37="",F37=""),"",F37*O37/1000*Lookups!$B$25) -> 0 | T37: =IF(AND($B37="Fugitive emissions",$C37="Refrigerant leaks"),J37,"") | U37: =IF(AND($B37="Fugitive emissions",$C37="Refrigerant leaks"),F37/1000,"")
A38: 1 | B38: Process Emission | C38: SRU process oxidation | D38: SRU process oxidation - U_13 | F38: 27000 | G38: tons sulfur | H38: =M38+N38*Lookups!$B$24+O38*Lookups!$B$25 -> 0.35 | I38: kg CO2e/ton sulfur | J38: =IF(Q38="","",Q38+R38+S38+IF(T38="",0,T38)) -> 9.45 | K38: Coke burn by mass balance / air flow + composition routinely monitored | L38: CO₂ (coke burn / flue gas mass balance) | M38: 0.35 | N38: 0 | O38: 0 | Q38: =IF(OR(M38="",F38=""),"",F38*M38/1000) -> 9.45 | R38: =IF(OR(N38="",F38=""),"",F38*N38/1000*Lookups!$B$24) -> 0 | S38: =IF(OR(O38="",F38=""),"",F38*O38/1000*Lookups!$B$25) -> 0 | T38: =IF(AND($B38="Fugitive emissions",$C38="Refrigerant leaks"),J38,"") | U38: =IF(AND($B38="Fugitive emissions",$C38="Refrigerant leaks"),F38/1000,"")
A39: 1 | B39: Process Emission | C39: SRU process oxidation | D39: SRU process oxidation - U_22 | F39: 27500 | G39: tons sulfur | H39: =M39+N39*Lookups!$B$24+O39*Lookups!$B$25 -> 0.35 | I39: kg CO2e/ton sulfur | J39: =IF(Q39="","",Q39+R39+S39+IF(T39="",0,T39)) -> 9.625 | K39: Coke burn by mass balance / air flow + composition routinely monitored | L39: CO₂ (coke burn / flue gas mass balance) | M39: 0.35 | N39: 0 | O39: 0 | Q39: =IF(OR(M39="",F39=""),"",F39*M39/1000) -> 9.625 | R39: =IF(OR(N39="",F39=""),"",F39*N39/1000*Lookups!$B$24) -> 0 | S39: =IF(OR(O39="",F39=""),"",F39*O39/1000*Lookups!$B$25) -> 0 | T39: =IF(AND($B39="Fugitive emissions",$C39="Refrigerant leaks"),J39,"") | U39: =IF(AND($B39="Fugitive emissions",$C39="Refrigerant leaks"),F39/1000,"")
A40: 1 | B40: stationary combusion | C40: Flare header reading | D40: Flare header reading | E40: Flare header Flowmeter - Stationary combusion | F40: 10000000 | G40: Nm3 | H40: =M40+N40*Lookups!$B$24+O40*Lookups!$B$25 -> 2.1021255 | I40: kg CO2e/Nm3 | J40: =IF(Q40="","",Q40+R40+S40+IF(T40="",0,T40)) -> 21021.255 | K40: Flared gas with continuous flow and periodic composition measurement | L40: Flares – CO₂ (combustion efficiency assumption) | M40: 2.1 | N40: 3.9e-05 | O40: 3.9e-06 | Q40: =IF(OR(M40="",F40=""),"",F40*M40/1000) -> 21000 | R40: =IF(OR(N40="",F40=""),"",F40*N40/1000*Lookups!$B$24) -> 10.92 | S40: =IF(OR(O40="",F40=""),"",F40*O40/1000*Lookups!$B$25) -> 10.335 | T40: =IF(AND($B40="Fugitive emissions",$C40="Refrigerant leaks"),J40,"") | U40: =IF(AND($B40="Fugitive emissions",$C40="Refrigerant leaks"),F40/1000,"")
...

Sheet Summary
B1: Scope | C1: CO2 Emissions (tCO2) | D1: CH4 Emissions (tCO2e) | E1: N2O Emissions (tCO2e) | F1: Fluorinated Gas Emissions (tCO2e) | G1: Total Emissions (tCO2e)
B2: Scope 1 | C2: =SUMIF(Activities!A:A,"=1",Activities!Q:Q) -> 2813317.5 | D2: =SUMIF(Activities!A:A,"=1",Activities!R:R) -> 1300.965 | E2: =SUMIF(Activities!A:A,"=1",Activities!S:S) -> 1241.1685 | F2: =SUMIF(Activities!A:A,"=1",Activities!T:T) -> 281.7783 | G2: =SUMIF(Activities!A:A,"=1",Activities!J:J) -> 2816141.5
B3: Scope 2 | C3: =SUMIF(Activities!A:A,"=2",Activities!Q:Q) -> 199898.4 | D3: =SUMIF(Activities!A:A,"=2",Activities!R:R) -> 0 | E3: =SUMIF(Activities!A:A,"=2",Activities!S:S) -> 0 | F3: =SUMIF(Activities!A:A,"=2",Activities!T:T) -> 0 | G3: =SUMIF(Activities!A:A,"=2",Activities!J:J) -> 199898.4
B4: Scope 3 | C4: =SUMIF(Activities!A:A,"=3",Activities!Q:Q) -> 16926521 | D4: =SUMIF(Activities!A:A,"=3",Activities!R:R) -> 18655.078 | E4: =SUMIF(Activities!A:A,"=3",Activities!S:S) -> 35048.823 | F4: =SUMIF(Activities!A:A,"=3",Activities!T:T) -> 0 | G4: =SUMIF(Activities!A:A,"=3",Activities!J:J) -> 16980225
B5: Total | C5: =SUM(C2:C4) -> 19939737 | D5: =SUM(D2:D4) -> 19956.043 | E5: =SUM(E2:E4) -> 36289.991 | F5: =SUM(F2:F4) -> 281.7783 | G5: =SUM(G2:G4) -> 19996265
B8: Category | C8: CO2 Emissions (tCO2) | D8: CH4 Emissions (tCO2e) | E8: N2O Emissions (tCO2e) | F8: Fluorinated Gas Emissions (tCO2e) | G8: Total Emissions (tCO2e)
B9: stationary combusion | C9: =SUMIF(Activities!B:B,"="&$B9,Activities!Q:Q) -> 2608830.9 | D9: =SUMIF(Activities!B:B,"="&$B9,Activities!R:R) -> 1299.9484 | E9: =SUMIF(Activities!B:B,"="&$B9,Activities!S:S) -> 1231.547 | F9: =SUMIF(Activities!B:B,"="&$B9,Activities!T:T) -> 0 | G9: =SUMIF(Activities!B:B,"="&$B9,Activities!J:J) -> 2611362.4
B10: Mobile combusion | C10: =SUMIF(Activities!B:B,"="&$B10,Activities!Q:Q) -> 690.1 | D10: =SUMIF(Activities!B:B,"="&$B10,Activities!R:R) -> 1.01661 | E10: =SUMIF(Activities!B:B,"="&$B10,Activities!S:S) -> 9.6214875 | F10: =SUMIF(Activities!B:B,"="&$B10,Activities!T:T) -> 0 | G10: =SUMIF(Activities!B:B,"="&$B10,Activities!J:J) -> 700.7381
B11: Fugitive emissions | C11: =SUMIF(Activities!B:B,"="&$B11,Activities!Q:Q) -> 3276.4959 | D11: =SUMIF(Activities!B:B,"="&$B11,Activities!R:R) -> 0 | E11: =SUMIF(Activities!B:B,"="&$B11,Activities!S:S) -> 0 | F11: =SUMIF(Activities!B:B,"="&$B11,Activities!T:T) -> 281.7783 | G11: =SUMIF(Activities!B:B,"="&$B11,Activities!J:J) -> 3558.2742
B12: Process Emission | C12: =SUMIF(Activities!B:B,"="&$B12,Activities!Q:Q) -> 200520.08 | D12: =SUMIF(Activities!B:B,"="&$B12,Activities!R:R) -> 0 | E12: =SUMIF(Activities!B:B,"="&$B12,Activities!S:S) -> 0 | F12: =SUMIF(Activities!B:B,"="&$B12,Activities!T:T) -> 0 | G12: =SUMIF(Activities!B:B,"="&$B12,Activities!J:J) -> 200520.08
B13: Scope 1 Total | C13: =C12+C11+C10+C9 -> 2813317.5 | D13: =D12+D11+D10+D9 -> 1300.965 | E13: =E12+E11+E10+E9 -> 1241.1685 | F13: =F12+F11+F10+F9 -> 281.7783 | G13: =G12+G11+G10+G9 -> 2816141.5
B14: Purchased electricity | C14: =SUMIF(Activities!B:B,"="&$B14,Activities!Q:Q) -> 199898.4 | D14: =SUMIF(Activities!B:B,"="&$B14,Activities!R:R) -> 0 | E14: =SUMIF(Activities!B:B,"="&$B14,Activities!S:S) -> 0 | F14: =SUMIF(Activities!B:B,"="&$B14,Activities!T:T) -> 0 | G14: =SUMIF(Activities!B:B,"="&$B14,Activities!J:J) -> 199898.4
B15: Scope 2 Total | C15: =C14 -> 199898.4 | D15: =D14 -> 0 | E15: =E14 -> 0 | F15: =F14 -> 0 | G15: =G14 -> 199898.4
B16: Employee comutee | C16: =SUMIF(Activities!B:B,"="&$B16,Activities!Q:Q) -> 48000 | D16: =SUMIF(Activities!B:B,"="&$B16,Activities!R:R) -> 0 | E16: =SUMIF(Activities!B:B,"="&$B16,Activities!S:S) -> 0 | F16: =SUMIF(Activities!B:B,"="&$B16,Activities!T:T) -> 0 | G16: =SUMIF(Activities!B:B,"="&$B16,Activities!J:J) -> 48000
B17: Use of Sold Products | C17: =SUMIF(Activities!B:B,"="&$B17,Activities!Q:Q) -> 16878521 | D17: =SUMIF(Activities!B:B,"="&$B17,Activities!R:R) -> 18655.078 | E17: =SUMIF(Activities!B:B,"="&$B17,Activities!S:S) -> 35048.823 | F17: =SUMIF(Activities!B:B,"="&$B17,Activities!T:T) -> 0 | G17: =SUMIF(Activities!B:B,"="&$B17,Activities!J:J) -> 16932225
B18: Scope 3 Total | C18: =C17+C16 -> 16926521 | D18: =D17+D16 -> 18655.078 | E18: =E17+E16 -> 35048.823 | F18: =F17+F16 -> 0 | G18: =G17+G16 -> 16980225
B19: Total Scope 1,2,3 | C19: =C18+C15+C13 -> 19939737 | D19: =D18+D15+D13 -> 19956.043 | E19: =E18+E15+E13 -> 36289.991 | F19: =F18+F15+F13 -> 281.7783 | G19: =G18+G15+G13 -> 19996265

Sheet Lookups
A1: AD Source | B1: AD_uncertainty_value | C1: AD_uncertainty_Refrence | E1: EF Source | F1: EF_uncertainty_value | G1: EF_uncertainty_Refrence
A2: Well Calibrated Meter | B2: 0.05 | C2: IPCC 2006 Guidelines, Vol.2, Ch.1 – default ±5% for fossil fuel activity data (high-quality meters). Aligned with ‘High’ data-quality rating in GHG Protocol | E2: CO₂ from stationary fuel combustion using site-specific carbon content (lab) | F2: 0.05 | G2: Assumed ±5% (95% CI) based on expert judgement Classified as ‘High’ data quality in GHG Protocol terms.
A3: Supplier Invoices | B3: 0.05 | C3: IPCC 2006 default ±5% for fossil fuel activity data, supplier invoices treated as high-quality activity data; consistent with GHG Protocol ‘High’ data quality. | E3: Robust national factors | F3: 0.1 | G3: GHG Protocol: combustion totals High/Good; site-specific carbon content
A4: Purchased electricity from utility meter | B4: 0.05 | C4: Assumed ±5% based on IPCC default for energy activity data; utility billing meters are high-quality meters (GHG Protocol ‘High’). | E4: DEFRA 2024 conversion factors | F4: 0.3 | G4: Assumed ±30% (95% CI) based on expert judgement For corporate inventory purposes we classify generic DEFRA factors as ‘Fair–Poor’ data quality (per GHG Protocol)
A5: Flared gas with continuous flow and periodic composition measurement | B5: 0.032 | C5: API/IPIECA ‘Addressing Uncertainty…’, flare measurement example (API MPMS 14.10) gives 3.2% combined uncertainty | E5: IPCC 2006 Vol.5 (Waste), Ch.6 – requires COD/BOD | F5: 0.3 | G5: Assumed ±30% (95% CI) based on expert judgement. IPCC 2006 Vol.5, Ch.6 notes that wastewater emission factors depend strongly on local treatment conditions and industrial mix and can be significantly more uncertain than fuel CO₂ factors. We therefore place default COD/BOD-based factors in the ‘Fair–Poor’ data quality band and use ±30% as a representative value
A6: Flared/vented gas estimated by valve positions/orifice equations (no meter) | B6: 0.3 | C6: Engineering estimate; assumed ±30% based on expert judgement. Classified as ‘Fair’ (low data quality) in GHG Protocol | E6: Process default | F6: 0.3 | G6: Assumed ±30% (95% CI) based on expert judgement. Default process emission factors without site- or country-specific data are substantially more uncertain than fuel CO₂ factors, so we classify them as ‘Fair’ data quality per GHG Protocol
A7: Any one-off estimate (nameplate × hours, rough back-calcs) | B7: 0.3 | C7: Engineering estimate; assumed ±30% based on expert judgement. Classified as ‘Fair’ (low data quality) in GHG Protocol | E7: EF sheet – Refrigerants (tCO2e/kg) | F7: 0.3 | G7: Assumed ±30% (95% CI) based on expert judgement. IPCC assessment reports indicate substantial (≈20–40%) uncertainty in GWPs and related parameters for many HFCs and other F-gases, much higher than for CO₂. We therefore classify default refrigerant factors as ‘Fair–Poor’ data quality and apply a representative ±30%.
A8: Coke burn by mass balance / air flow + composition routinely monitored | B8: 0.3 | C8: Engineering estimate; assumed ±30% based on expert judgement. Classified as ‘Fair’ (low data quality) in GHG Protocol | E8: IPCC 2006 (Vol.2 Energy, default fuel carbon content) | F8: 0.3 | G8: Defaults are variable vs. CO₂ → Fair–Poor band
E9: Flares – CO₂ (combustion efficiency assumption) | F9: 0.05 | G9: Assumed ±5% (95% CI) based on expert judgement Classified as ‘High’ data quality in GHG Protocol terms.
E10: Flares – CH₄ | F10: 0.75 | G10: IPCC Volume 2 Chapter 4
E11: CO₂ (coke burn / flue gas mass balance) | F11: 0.05 | G11: Assumed ±5% (95% CI) based on expert judgement. Classified as ‘High’ data quality in GHG Protocol terms.
E12: DEFRA 2024 conversion factors / 2021-API-GHG-Compendium with conversion from KG CO2e /MMBTU to KG CO2e/Litre | F12: 0.3 | G12: Assumed ±30% (95% CI) based on expert judgement. Contains complex calculations with high uncertainity ( fair as per GHG protocol )
E13: EPA AP- 42 to calculate Evaporative emissions from tanks then /DEFRA 2024 conversion factors | F13: 0.3 | G13: Assumed ±30% (95% CI) based on expert judgement. Contains complex calculations with high uncertainity ( fair as per GHG protocol )
E14: Fugitives (CH₄/CO₂) – factors | F14: 2.5 | G14: IPCC Volume 2 Chapter 4
A24: GWP_CH4_100yr | B24: 28 | C24: Default 100-yr GWP for CH4 (update if using AR6 or other basis)
A25: GWP_N2O_100yr | B25: 265 | C25: Default 100-yr GWP for N2O (update if using AR6 or other basis)

Sheet uncertainty_total
A1: Source description | B1: Activity Data | C1: AD Unit | D1: u_AD (rel) | E1: Emission Factor | F1: EF Unit | G1: u_EF (rel) | H1: A × D (kg CO2e) | I1: G / 1000 (tCO2e) | J1: A×u_AD (aux) | K1: D×u_EF (aux) | L1: u_source (rel) = √(C²+F²) | M1: (u_source × K)²
A2: ="[Scope " & Activities!$A$2 & "] " & Activities!$B$2 & " | " & Activities!$C$2 & " | " & Activities!$D$2 -> [Scope 1] stationary combusion | Heters/boiler fuel gas firing | Heters/boiler fuel gas firing - U_01 heater fuel firing | B2: =Activities!$F$2 -> 2687902 | C2: =Activities!$G$2 -> GJ | D2: =VLOOKUP(Activities!K2,Lookups!$A:$C,2,FALSE) -> 0.05 | E2: =Activities!M2 -> 56.1 | F2: =Activities!$I$2 -> kg CO2e/GJ | G2: =VLOOKUP(Activities!L2,Lookups!$E:$G,2,FALSE) -> 0.05 | H2: =IF(ISNUMBER(SEARCH("kg",F2)),B2*E2,B2*E2*1000) -> 1.507913e+08 | I2: =H2/1000 -> 150791.3 | J2: =B2*D2 -> 134395.1 | K2: =E2*G2 -> 2.805 | L2: =SQRT(D2^2+G2^2) -> 0.070710678 | M2: =(L2*I2)^2 -> 1.1369008e+08
A3: ="[Scope " & Activities!$A$3 & "] " & Activities!$B$3 & " | " & Activities!$C$3 & " | " & Activities!$D$3 -> [Scope 1] stationary combusion | Heters/boiler fuel gas firing | Heters/boiler fuel gas firing - U_17 heater fuel firing | B3: =Activities!$F$3 -> 2741660 | C3: =Activities!$G$3 -> GJ | D3: =VLOOKUP(Activities!K3,Lookups!$A:$C,2,FALSE) -> 0.05 | E3: =Activities!M3 -> 56.1 | F3: =Activities!$I$3 -> kg CO2e/GJ | G3: =VLOOKUP(Activities!L3,Lookups!$E:$G,2,FALSE) -> 0.05 | H3: =IF(ISNUMBER(SEARCH("kg",F3)),B3*E3,B3*E3*1000) -> 153807126 | I3: =H3/1000 -> 153807.13 | J3: =B3*D3 -> 137083 | K3: =E3*G3 -> 2.805 | L3: =SQRT(D3^2+G3^2) -> 0.070710678 | M3: =(L3*I3)^2 -> 1.1828316e+08
A4: ="[Scope " & Activities!$A$4 & "] " & Activities!$B$4 & " | " & Activities!$C$4 & " | " & Activities!$D$4 -> [Scope 1] stationary combusion | Heters/boiler fuel gas firing | Heters/boiler fuel gas firing - U02/03 heter firing | B4: =Activities!$F$4 -> 2795418 | C4: =Activities!$G$4 -> GJ | D4: =VLOOKUP(Activities!K4,Lookups!$A:$C,2,FALSE) -> 0.05 | E4: =Activities!M4 -> 56.1 | F4: =Activities!$I$4 -> kg CO2e/GJ | G4: =VLOOKUP(Activities!L4,Lookups!$E:$G,2,FALSE) -> 0.05 | H4: =IF(ISNUMBER(SEARCH("kg",F4)),B4*E4,B4*E4*1000) -> 1.5682295e+08 | I4: =H4/1000 -> 156822.95 | J4: =B4*D4 -> 139770.9 | K4: =E4*G4 -> 2.805 | L4: =SQRT(D4^2+G4^2) -> 0.070710678 | M4: =(L4*I4)^2 -> 1.2296719e+08
A5: ="[Scope " & Activities!$A$5 & "] " & Activities!$B$5 & " | " & Activities!$C$5 & " | " & Activities!$D$5 -> [Scope 1] stationary combusion | Heters/boiler fuel gas firing | Heters/boiler fuel gas firing - U_04 heater firing | B5: =Activities!$F$5 -> 2849176 | C5: =Activities!$G$5 -> GJ | D5: =VLOOKUP(Activities!K5,Lookups!$A:$C,2,FALSE) -> 0.05 | E5: =Activities!M5 -> 56.1 | F5: =Activities!$I$5 -> kg CO2e/GJ | G5: =VLOOKUP(Activities!L5,Lookups!$E:$G,2,FALSE) -> 0.05 | H5: =IF(ISNUMBER(SEARCH("kg",F5)),B5*E5,B5*E5*1000) -> 1.5983877e+08 | I5: =H5/1000 -> 159838.77 | J5: =B5*D5 -> 142458.8 | K5: =E5*G5 -> 2.805 | L5: =SQRT(D5^2+G5^2) -> 0.070710678 | M5: =(L5*I5)^2 -> 1.2774217e+08
A6: ="[Scope " & Activities!$A$6 & "] " & Activities!$B$6 & " | " & Activities!$C$6 & " | " & Activities!$D$6 -> [Scope 1] stationary combusion | Heters/boiler fuel gas firing | Heters/boiler fuel gas firing - U_07 heter firing | B6: =Activities!$F$6 -> 2902934 | C6: =Activities!$G$6 -> GJ | D6: =VLOOKUP(Activities!K6,Lookups!$A:$C,2,FALSE) -> 0.05 | E6: =Activities!M6 -> 56.1 | F6: =Activities!$I$6 -> kg CO2e/GJ | G6: =VLOOKUP(Activities!L6,Lookups!$E:$G,2,FALSE) -> 0.05 | H6: =IF(ISNUMBER(SEARCH("kg",F6)),B6*E6,B6*E6*1000) -> 1.628546e+08 | I6: =H6/1000 -> 162854.6 | J6: =B6*D6 -> 145146.7 | K6: =E6*G6 -> 2.805 | L6: =SQRT(D6^2+G6^2) -> 0.070710678 | M6: =(L6*I6)^2 -> 1.326081e+08
A7: ="[Scope " & Activities!$A$7 & "] " & Activities!$B$7 & " | " & Activities!$C$7 & " | " & Activities!$D$7 -> [Scope 1] stationary combusion | Heters/boiler fuel gas firing | Heters/boiler fuel gas firing - U_08 heater firing | B7: =Activities!$F$7 -> 2956692 | C7: =Activities!$G$7 -> GJ | D7: =VLOOKUP(Activities!K7,Lookups!$A:$C,2,FALSE) -> 0.05 | E7: =Activities!M7 -> 56.1 | F7: =Activities!$I$7 -> kg CO2e/GJ | G7: =VLOOKUP(Activities!L7,Lookups!$E:$G,2,FALSE) -> 0.05 | H7: =IF(ISNUMBER(SEARCH("kg",F7)),B7*E7,B7*E7*1000) -> 1.6587042e+08 | I7: =H7/1000 -> 165870.42 | J7: =B7*D7 -> 147834.6 | K7: =E7*G7 -> 2.805 | L7: =SQRT(D7^2+G7^2) -> 0.070710678 | M7: =(L7*I7)^2 -> 1.3756498e+08
A8: ="[Scope " & Activities!$A$8 & "] " & Activities!$B$8 & " | " & Activities!$C$8 & " | " & Activities!$D$8 -> [Scope 1] stationary combusion | Heters/boiler fuel gas firing | Heters/boiler fuel gas firing - U_09 heater firing | B8: =Activities!$F$8 -> 3010450 | C8: =Activities!$G$8 -> GJ | D8: =VLOOKUP(Activities!K8,Lookups!$A:$C,2,FALSE) -> 0.05 | E8: =Activities!M8 -> 56.1 | F8: =Activities!$I$8 -> kg CO2e/GJ | G8: =VLOOKUP(Activities!L8,Lookups!$E:$G,2,FALSE) -> 0.05 | H8: =IF(ISNUMBER(SEARCH("kg",F8)),B8*E8,B8*E8*1000) -> 168886245 | I8: =H8/1000 -> 168886.24 | J8: =B8*D8 -> 150522.5 | K8: =E8*G8 -> 2.805 | L8: =SQRT(D8^2+G8^2) -> 0.070710678 | M8: =(L8*I8)^2 -> 1.4261282e+08
A9: ="[Scope " & Activities!$A$9 & "] " & Activities!$B$9 & " | " & Activities!$C$9 & " | " & Activities!$D$9 -> [Scope 1] stationary combusion | Heters/boiler fuel gas firing | Heters/boiler fuel gas firing - U_11 heater firing | B9: =Activities!$F$9 -> 3064208 | C9: =Activities!$G$9 -> GJ | D9: =VLOOKUP(Activities!K9,Lookups!$A:$C,2,FALSE) -> 0.05 | E9: =Activities!M9 -> 56.1 | F9: =Activities!$I$9 -> kg CO2e/GJ | G9: =VLOOKUP(Activities!L9,Lookups!$E:$G,2,FALSE) -> 0.05 | H9: =IF(ISNUMBER(SEARCH("kg",F9)),B9*E9,B9*E9*1000) -> 1.7190207e+08 | I9: =H9/1000 -> 171902.07 | J9: =B9*D9 -> 153210.4 | K9: =E9*G9 -> 2.805 | L9: =SQRT(D9^2+G9^2) -> 0.070710678 | M9: =(L9*I9)^2 -> 1.4775161e+08
A10: ="[Scope " & Activities!$A$10 & "] " & Activities!$B$10 & " | " & Activities!$C$10 & " | " & Activities!$D$10 -> [Scope 1] stationary combusion | Heters/boiler fuel gas firing | Heters/boiler fuel gas firing - U_11_cell3 heater firing | B10: =Activities!$F$10 -> 3117966 | C10: =Activities!$G$10 -> GJ | D10: =VLOOKUP(Activities!K10,Lookups!$A:$C,2,FALSE) -> 0.05 | E10: =Activities!M10 -> 56.1 | F10: =Activities!$I$10 -> kg CO2e/GJ | G10: =VLOOKUP(Activities!L10,Lookups!$E:$G,2,FALSE) -> 0.05 | H10: =IF(ISNUMBER(SEARCH("kg",F10)),B10*E10,B10*E10*1000) -> 1.7491789e+08 | I10: =H10/1000 -> 174917.89 | J10: =B10*D10 -> 155898.3 | K10: =E10*G10 -> 2.805 | L10: =SQRT(D10^2+G10^2) -> 0.070710678 | M10: =(L10*I10)^2 -> 1.5298135e+08
A11: ="[Scope " & Activities!$A$11 & "] " & Activities!$B$11 & " | " & Activities!$C$11 & " | " & Activities!$D$11 -> [Scope 1] stationary combusion | Heters/boiler fuel gas firing | Heters/boiler fuel gas firing - U_18 heater firing | B11: =Activities!$F$11 -> 3171724 | C11: =Activities!$G$11 -> GJ | D11: =VLOOKUP(Activities!K11,Lookups!$A:$C,2,FALSE) -> 0.05 | E11: =Activities!M11 -> 56.1 | F11: =Activities!$I$11 -> kg CO2e/GJ | G11: =VLOOKUP(Activities!L11,Lookups!$E:$G,2,FALSE) -> 0.05 | H11: =IF(ISNUMBER(SEARCH("kg",F11)),B11*E11,B11*E11*1000) -> 1.7793372e+08 | I11: =H11/1000 -> 177933.72 | J11: =B11*D11 -> 158586.2 | K11: =E11*G11 -> 2.805 | L11: =SQRT(D11^2+G11^2) -> 0.070710678 | M11: =(L11*I11)^2 -> 1.5830204e+08
A12: ="[Scope " & Activities!$A$12 & "] " & Activities!$B$12 & " | " & Activities!$C$12 & " | " & Activities!$D$12 -> [Scope 1] stationary combusion | Heters/boiler fuel gas firing | Heters/boiler fuel gas firing - U_19 heater firing | B12: =Activities!$F$12 -> 3225482 | C12: =Activities!$G$12 -> GJ | D12: =VLOOKUP(Activities!K12,Lookups!$A:$C,2,FALSE) -> 0.05 | E12: =Activities!M12 -> 56.1 | F12: =Activities!$I$12 -> kg CO2e/GJ | G12: =VLOOKUP(Activities!L12,Lookups!$E:$G,2,FALSE) -> 0.05 | H12: =IF(ISNUMBER(SEARCH("kg",F12)),B12*E12,B12*E12*1000) -> 1.8094954e+08 | I12: =H12/1000 -> 180949.54 | J12: =B12*D12 -> 161274.1 | K12: =E12*G12 -> 2.805 | L12: =SQRT(D12^2+G12^2) -> 0.070710678 | M12: =(L12*I12)^2 -> 1.6371368e+08
A13: ="[Scope " & Activities!$A$13 & "] " & Activities!$B$13 & " | " & Activities!$C$13 & " | " & Activities!$D$13 -> [Scope 1] stationary combusion | Heters/boiler fuel gas firing | Heters/boiler fuel gas firing - U_20 heater firing | B13: =Activities!$F$13 -> 3279240 | C13: =Activities!$G$13 -> GJ | D13: =VLOOKUP(Activities!K13,Lookups!$A:$C,2,FALSE) -> 0.05 | E13: =Activities!M13 -> 56.1 | F13: =Activities!$I$13 -> kg CO2e/GJ | G13: =VLOOKUP(Activities!L13,Lookups!$E:$G,2,FALSE) -> 0.05 | H13: =IF(ISNUMBER(SEARCH("kg",F13)),B13*E13,B13*E13*1000) -> 183965364 | I13: =H13/1000 -> 183965.36 | J13: =B13*D13 -> 163962 | K13: =E13*G13 -> 2.805 | L13: =SQRT(D13^2+G13^2) -> 0.070710678 | M13: =(L13*I13)^2 -> 1.6921628e+08
A14: ="[Scope " & Activities!$A$14 & "] " & Activities!$B$14 & " | " & Activities!$C$14 & " | " & Activities!$D$14 -> [Scope 1] stationary combusion | Heters/boiler fuel gas firing | Heters/boiler fuel gas firing - U_21 heater firing | B14: =Activities!$F$14 -> 3332998 | C14: =Activities!$G$14 -> GJ | D14: =VLOOKUP(Activities!K14,Lookups!$A:$C,2,FALSE) -> 0.05 | E14: =Activities!M14 -> 56.1 | F14: =Activities!$I$14 -> kg CO2e/GJ | G14: =VLOOKUP(Activities!L14,Lookups!$E:$G,2,FALSE) -> 0.05 | H14: =IF(ISNUMBER(SEARCH("kg",F14)),B14*E14,B14*E14*1000) -> 1.8698119e+08 | I14: =H14/1000 -> 186981.19 | J14: =B14*D14 -> 166649.9 | K14: =E14*G14 -> 2.805 | L14: =SQRT(D14^2+G14^2) -> 0.070710678 | M14: =(L14*I14)^2 -> 1.7480982e+08
A15: ="[Scope " & Activities!$A$15 & "] " & Activities!$B$15 & " | " & Activities!$C$15 & " | " & Activities!$D$15 -> [Scope 1] stationary combusion | Heters/boiler fuel gas firing | Heters/boiler fuel gas firing - U_37 boilers firing | B15: =Activities!$F$15 -> 3386756 | C15: =Activities!$G$15 -> GJ | D15: =VLOOKUP(Activities!K15,Lookups!$A:$C,2,FALSE) -> 0.05 | E15: =Activities!M15 -> 56.1 | F15: =Activities!$I$15 -> kg CO2e/GJ | G15: =VLOOKUP(Activities!L15,Lookups!$E:$G,2,FALSE) -> 0.05 | H15: =IF(ISNUMBER(SEARCH("kg",F15)),B15*E15,B15*E15*1000) -> 1.8999701e+08 | I15: =H15/1000 -> 189997.01 | J15: =B15*D15 -> 169337.8 | K15: =E15*G15 -> 2.805 | L15: =SQRT(D15^2+G15^2) -> 0.070710678 | M15: =(L15*I15)^2 -> 1.8049432e+08
A16: ="[Scope " & Activities!$A$16 & "] " & Activities!$B$16 & " | " & Activities!$C$16 & " | " & Activities!$D$16 -> [Scope 1] stationary combusion | Incenerator firing | Incenerator firing - U_13 firing | B16: =Activities!$F$16 -> 1720257 | C16: =Activities!$G$16 -> GJ | D16: =VLOOKUP(Activities!K16,Lookups!$A:$C,2,FALSE) -> 0.05 | E16: =Activities!M16 -> 58 | F16: =Activities!$I$16 -> kg CO2e/GJ | G16: =VLOOKUP(Activities!L16,Lookups!$E:$G,2,FALSE) -> 0.05 | H16: =IF(ISNUMBER(SEARCH("kg",F16)),B16*E16,B16*E16*1000) -> 99774906 | I16: =H16/1000 -> 99774.906 | J16: =B16*D16 -> 86012.85 | K16: =E16*G16 -> 2.9 | L16: =SQRT(D16^2+G16^2) -> 0.070710678 | M16: =(L16*I16)^2 -> 49775159
A17: ="[Scope " & Activities!$A$17 & "] " & Activities!$B$17 & " | " & Activities!$C$17 & " | " & Activities!$D$17 -> [Scope 1] stationary combusion | Incenerator firing | Incenerator firing - U_22 firing | B17: =Activities!$F$17 -> 1747136 | C17: =Activities!$G$17 -> GJ | D17: =VLOOKUP(Activities!K17,Lookups!$A:$C,2,FALSE) -> 0.05 | E17: =Activities!M17 -> 58 | F17: =Activities!$I$17 -> kg CO2e/GJ | G17: =VLOOKUP(Activities!L17,Lookups!$E:$G,2,FALSE) -> 0.05 | H17: =IF(ISNUMBER(SEARCH("kg",F17)),B17*E17,B17*E17*1000) -> 101333888 | I17: =H17/1000 -> 101333.89 | J17: =B17*D17 -> 87356.8 | K17: =E17*G17 -> 2.9 | L17: =SQRT(D17^2+G17^2) -> 0.070710678 | M17: =(L17*I17)^2 -> 51342784
A18: ="[Scope " & Activities!$A$18 & "] " & Activities!$B$18 & " | " & Activities!$C$18 & " | " & Activities!$D$18 -> [Scope 1] stationary combusion | Fuel oil firing | Fuel oil firing | B18: =Activities!$F$18 -> 15000 | C18: =Activities!$G$18 -> GJ | D18: =VLOOKUP(Activities!K18,Lookups!$A:$C,2,FALSE) -> 0.05 | E18: =Activities!M18 -> 77.4 | F18: =Activities!$I$18 -> kg CO2e/GJ | G18: =VLOOKUP(Activities!L18,Lookups!$E:$G,2,FALSE) -> 0.05 | H18: =IF(ISNUMBER(SEARCH("kg",F18)),B18*E18,B18*E18*1000) -> 1161000 | I18: =H18/1000 -> 1161 | J18: =B18*D18 -> 750 | K18: =E18*G18 -> 3.87 | L18: =SQRT(D18^2+G18^2) -> 0.070710678 | M18: =(L18*I18)^2 -> 6739.605
A19: ="[Scope " & Activities!$A$19 & "] " & Activities!$B$19 & " | " & Activities!$C$19 & " | " & Activities!$D$19 -> [Scope 1] stationary combusion | Diesel firing | Diesel firing - Electric substations | B19: =Activities!$F$19 -> 10000 | C19: =Activities!$G$19 -> L | D19: =VLOOKUP(Activities!K19,Lookups!$A:$C,2,FALSE) -> 0.05 | E19: =Activities!M19 -> 2.68 | F19: =Activities!$I$19 -> kg CO2e/L | G19: =VLOOKUP(Activities!L19,Lookups!$E:$G,2,FALSE) -> 0.3 | H19: =IF(ISNUMBER(SEARCH("kg",F19)),B19*E19,B19*E19*1000) -> 26800 | I19: =H19/1000 -> 26.8 | J19: =B19*D19 -> 500 | K19: =E19*G19 -> 0.804 | L19: =SQRT(D19^2+G19^2) -> 0.30413813 | M19: =(L19*I19)^2 -> 66.4372
A20: ="[Scope " & Activities!$A$20 & "] " & Activities!$B$20 & " | " & Activities!$C$20 & " | " & Activities!$D$20 -> [Scope 1] stationary combusion | Diesel firing | Diesel firing - Disel Fire pumps | B20: =Activities!$F$20 -> 6000 | C20: =Activities!$G$20 -> L | D20: =VLOOKUP(Activities!K20,Lookups!$A:$C,2,FALSE) -> 0.05 | E20: =Activities!M20 -> 2.68 | F20: =Activities!$I$20 -> kg CO2e/L | G20: =VLOOKUP(Activities!L20,Lookups!$E:$G,2,FALSE) -> 0.3 | H20: =IF(ISNUMBER(SEARCH("kg",F20)),B20*E20,B20*E20*1000) -> 16080 | I20: =H20/1000 -> 16.08 | J20: =B20*D20 -> 300 | K20: =E20*G20 -> 0.804 | L20: =SQRT(D20^2+G20^2) -> 0.30413813 | M20: =(L20*I20)^2 -> 23.917392
A21: ="[Scope " & Activities!$A$21 & "] " & Activities!$B$21 & " | " & Activities!$C$21 & " | " & Activities!$D$21 -> [Scope 1] Mobile combusion | Diesel | Diesel - Forklifts | B21: =Activities!$F$21 -> 180000 | C21: =Activities!$G$21 -> L diesel | D21: =VLOOKUP(Activities!K21,Lookups!$A:$C,2,FALSE) -> 0.05 | E21: =Activities!M21 -> 2.68 | F21: =Activities!$I$21 -> kg CO2e/L | G21: =VLOOKUP(Activities!L21,Lookups!$E:$G,2,FALSE) -> 0.3 | H21: =IF(ISNUMBER(SEARCH("kg",F21)),B21*E21,B21*E21*1000) -> 482400 | I21: =H21/1000 -> 482.4 | J21: =B21*D21 -> 9000 | K21: =E21*G21 -> 0.804 | L21: =SQRT(D21^2+G21^2) -> 0.30413813 | M21: =(L21*I21)^2 -> 21525.653
A22: ="[Scope " & Activities!$A$22 & "] " & Activities!$B$22 & " | " & Activities!$C$22 & " | " & Activities!$D$22 -> [Scope 1] Mobile combusion | Diesel | Diesel - Fire vehicle | B22: =Activities!$F$22 -> 20000 | C22: =Activities!$G$22 -> L diesel | D22: =VLOOKUP(Activities!K22,Lookups!$A:$C,2,FALSE) -> 0.05 | E22: =Activities!M22 -> 2.68 | F22: =Activities!$I$22 -> kg CO2e/L | G22: =VLOOKUP(Activities!L22,Lookups!$E:$G,2,FALSE) -> 0.3 | H22: =IF(ISNUMBER(SEARCH("kg",F22)),B22*E22,B22*E22*1000) -> 53600 | I22: =H22/1000 -> 53.6 | J22: =B22*D22 -> 1000 | K22: =E22*G22 -> 0.804 | L22: =SQRT(D22^2+G22^2) -> 0.30413813 | M22: =(L22*I22)^2 -> 265.7488
A23: ="[Scope " & Activities!$A$23 & "] " & Activities!$B$23 & " | " & Activities!$C$23 & " | " & Activities!$D$23 -> [Scope 1] Mobile combusion | Diesel | Diesel - maintinance vehicles | B23: =Activities!$F$23 -> 28500 | C23: =Activities!$G$23 -> L diesel | D23: =VLOOKUP(Activities!K23,Lookups!$A:$C,2,FALSE) -> 0.05 | E23: =Activities!M23 -> 2.68 | F23: =Activities!$I$23 -> kg CO2e/L | G23: =VLOOKUP(Activities!L23,Lookups!$E:$G,2,FALSE) -> 0.3 | H23: =IF(ISNUMBER(SEARCH("kg",F23)),B23*E23,B23*E23*1000) -> 76380 | I23: =H23/1000 -> 76.38 | J23: =B23*D23 -> 1425 | K23: =E23*G23 -> 0.804 | L23: =SQRT(D23^2+G23^2) -> 0.30413813 | M23: =(L23*I23)^2 -> 539.63616
A24: ="[Scope " & Activities!$A$24 & "] " & Activities!$B$24 & " | " & Activities!$C$24 & " | " & Activities!$D$24 -> [Scope 1] Mobile combusion | Diesel | Diesel - shuttle/Bus movements | B24: =Activities!$F$24 -> 29000 | C24: =Activities!$G$24 -> L diesel | D24: =VLOOKUP(Activities!K24,Lookups!$A:$C,2,FALSE) -> 0.05 | E24: =Activities!M24 -> 2.68 | F24: =Activities!$I$24 -> kg CO2e/L | G24: =VLOOKUP(Activities!L24,Lookups!$E:$G,2,FALSE) -> 0.3 | H24: =IF(ISNUMBER(SEARCH("kg",F24)),B24*E24,B24*E24*1000) -> 77720 | I24: =H24/1000 -> 77.72 | J24: =B24*D24 -> 1450 | K24: =E24*G24 -> 0.804 | L24: =SQRT(D24^2+G24^2) -> 0.30413813 | M24: =(L24*I24)^2 -> 558.73685
A25: ="[Scope " & Activities!$A$25 & "] " & Activities!$B$25 & " | " & Activities!$C$25 & " | " & Activities!$D$25 -> [Scope 1] Fugitive emissions | Storage tanks breathing & working losses | Storage tanks breathing & working losses - Crude Tanks | B25: =Activities!$F$25 -> 8124251 | C25: =Activities!$G$25 -> m3 throughput | D25: =VLOOKUP(Activities!K25,Lookups!$A:$C,2,FALSE) -> 0.05 | E25: =Activities!M25 -> 0.15 | F25: =Activities!$I$25 -> kg CO2e/m3 | G25: =VLOOKUP(Activities!L25,Lookups!$E:$G,2,FALSE) -> 0.3 | H25: =IF(ISNUMBER(SEARCH("kg",F25)),B25*E25,B25*E25*1000) -> 1218637.6 | I25: =H25/1000 -> 1218.6376 | J25: =B25*D25 -> 406212.55 | K25: =E25*G25 -> 0.045 | L25: =SQRT(D25^2+G25^2) -> 0.30413813 | M25: =(L25*I25)^2 -> 137369.69
A26: ="[Scope " & Activities!$A$26 & "] " & Activities!$B$26 & " | " & Activities!$C$26 & " | " & Activities!$D$26 -> [Scope 1] Fugitive emissions | Storage tanks breathing & working losses | Storage tanks breathing & working losses - LPG tanks | B26: =Activities!$F$26 -> 406213 | C26: =Activities!$G$26 -> m3 throughput | D26: =VLOOKUP(Activities!K26,Lookups!$A:$C,2,FALSE) -> 0.05 | E26: =Activities!M26 -> 0.15 | F26: =Activities!$I$26 -> kg CO2e/m3 | G26: =VLOOKUP(Activities!L26,Lookups!$E:$G,2,FALSE) -> 0.3 | H26: =IF(ISNUMBER(SEARCH("kg",F26)),B26*E26,B26*E26*1000) -> 60931.95 | I26: =H26/1000 -> 60.93195 | J26: =B26*D26 -> 20310.65 | K26: =E26*G26 -> 0.045 | L26: =SQRT(D26^2+G26^2) -> 0.30413813 | M26: =(L26*I26)^2 -> 343.42498
A27: ="[Scope " & Activities!$A$27 & "] " & Activities!$B$27 & " | " & Activities!$C$27 & " | " & Activities!$D$27 -> [Scope 1] Fugitive emissions | Storage tanks breathing & working losses | Storage tanks breathing & working losses - Naphtha Tanks | B27: =Activities!$F$27 -> 2031063 | C27: =Activities!$G$27 -> m3 throughput | D27: =VLOOKUP(Activities!K27,Lookups!$A:$C,2,FALSE) -> 0.05 | E27: =Activities!M27 -> 0.15 | F27: =Activities!$I$27 -> kg CO2e/m3 | G27: =VLOOKUP(Activities!L27,Lookups!$E:$G,2,FALSE) -> 0.3 | H27: =IF(ISNUMBER(SEARCH("kg",F27)),B27*E27,B27*E27*1000) -> 304659.45 | I27: =H27/1000 -> 304.65945 | J27: =B27*D27 -> 101553.15 | K27: =E27*G27 -> 0.045 | L27: =SQRT(D27^2+G27^2) -> 0.30413813 | M27: =(L27*I27)^2 -> 8585.6077
A28: ="[Scope " & Activities!$A$28 & "] " & Activities!$B$28 & " | " & Activities!$C$28 & " | " & Activities!$D$28 -> [Scope 1] Fugitive emissions | Storage tanks breathing & working losses | Storage tanks breathing & working losses - Kerosene Tanks | B28: =Activities!$F$28 -> 812425 | C28: =Activities!$G$28 -> m3 throughput | D28: =VLOOKUP(Activities!K28,Lookups!$A:$C,2,FALSE) -> 0.05 | E28: =Activities!M28 -> 0.15 | F28: =Activities!$I$28 -> kg CO2e/m3 | G28: =VLOOKUP(Activities!L28,Lookups!$E:$G,2,FALSE) -> 0.3 | H28: =IF(ISNUMBER(SEARCH("kg",F28)),B28*E28,B28*E28*1000) -> 121863.75 | I28: =H28/1000 -> 121.86375 | J28: =B28*D28 -> 40621.25 | K28: =E28*G28 -> 0.045 | L28: =SQRT(D28^2+G28^2) -> 0.30413813 | M28: =(L28*I28)^2 -> 1373.6966
A29: ="[Scope " & Activities!$A$29 & "] " & Activities!$B$29 & " | " & Activities!$C$29 & " | " & Activities!$D$29 -> [Scope 1] Fugitive emissions | Storage tanks breathing & working losses | Storage tanks breathing & working losses - Diesel Tanks | B29: =Activities!$F$29 -> 2843488 | C29: =Activities!$G$29 -> m3 throughput | D29: =VLOOKUP(Activities!K29,Lookups!$A:$C,2,FALSE) -> 0.05 | E29: =Activities!M29 -> 0.15 | F29: =Activities!$I$29 -> kg CO2e/m3 | G29: =VLOOKUP(Activities!L29,Lookups!$E:$G,2,FALSE) -> 0.3 | H29: =IF(ISNUMBER(SEARCH("kg",F29)),B29*E29,B29*E29*1000) -> 426523.2 | I29: =H29/1000 -> 426.5232 | J29: =B29*D29 -> 142174.4 | K29: =E29*G29 -> 0.045 | L29: =SQRT(D29^2+G29^2) -> 0.30413813 | M29: =(L29*I29)^2 -> 16827.789
